<sdf version='1.7'>
  <world name='cc22_track_v1'>
    <model name='track'>
      <static>1</static>
      <link name='track'>
        <collision name='collision'>
          <geometry>
            <plane>
              <normal>0 0 1</normal>
              <size>20 10</size>
            </plane>
          </geometry>
          <surface>
            <friction>
              <ode>
                <mu>100</mu>
                <mu2>50</mu2>
              </ode>
              <torsional>
                <ode/>
              </torsional>
            </friction>
            <contact>
              <ode/>
            </contact>
            <bounce/>
          </surface>
          <max_contacts>10</max_contacts>
        </collision>
        <visual name='visual'>
          <cast_shadows>0</cast_shadows>
          <geometry>
            <plane>
              <normal>0 0 1</normal>
              <size>20 10</size>
            </plane>
          </geometry>
          <material>
            <script>
              <uri>model://cc22_track_v1/materials/scripts</uri>
              <uri>model://cc22_track_v1/materials/textures</uri>
              <name>basic_track/Image</name>
            </script>
          </material>
        </visual>
        <self_collide>0</self_collide>
        <enable_wind>0</enable_wind>
        <kinematic>0</kinematic>
      </link>
      <pose>9.19 4.29 0 0 -0 0</pose>
    </model>
    <gravity>0 0 -9.8</gravity>
    <magnetic_field>6e-06 2.3e-05 -4.2e-05</magnetic_field>
    <atmosphere type='adiabatic'/>
    <physics type='ode'>
      <max_step_size>0.001</max_step_size>
      <real_time_factor>1</real_time_factor>
      <real_time_update_rate>1000</real_time_update_rate>
    </physics>
    <scene>
      <ambient>0.4 0.4 0.4 1</ambient>
      <background>0.7 0.7 0.7 1</background>
      <shadows>1</shadows>
    </scene>
    <wind/>
    <spherical_coordinates>
      <surface_model>EARTH_WGS84</surface_model>
      <latitude_deg>0</latitude_deg>
      <longitude_deg>0</longitude_deg>
      <elevation>0</elevation>
      <heading_deg>0</heading_deg>
    </spherical_coordinates>
    <model name='robot'>
      <link name='selfie2021'>
        <inertial>
          <pose>0.108911 0 0.000994 0 -0 0</pose>
          <mass>101.04</mass>
          <inertia>
            <ixx>0.473303</ixx>
            <ixy>-1.35525e-20</ixy>
            <ixz>0.010891</ixz>
            <iyy>0.916119</iyy>
            <iyz>-1.32235e-06</iyz>
            <izz>0.796279</izz>
          </inertia>
        </inertial>
        <visual name='selfie2021_fixed_joint_lump__base_link_visual'>
          <pose>0.11 0 0 0 -0 0</pose>
          <geometry>
            <mesh>
              <scale>1 1 1</scale>
              <uri>/home/kamil/selfie/carolocup/src/Simulation/gazebo_selfie_sim/vehicles/models/selfie/meshes/my_chasis.STL</uri>
            </mesh>
          </geometry>
          <material>
            <script>
              <name>Gazebo/Red</name>
              <uri>file://media/materials/scripts/gazebo.material</uri>
            </script>
          </material>
        </visual>
        <visual name='selfie2021_fixed_joint_lump__mast_link_visual_1'>
          <pose>-0.02 0 0.1051 0 -0 0</pose>
          <geometry>
            <cylinder>
              <length>0.21</length>
              <radius>0.01</radius>
            </cylinder>
          </geometry>
          <material>
            <script>
              <name>Gazebo/DarkGray</name>
              <uri>file://media/materials/scripts/gazebo.material</uri>
            </script>
          </material>
        </visual>
        <visual name='selfie2021_fixed_joint_lump__camera_link_visual_2'>
          <pose>0.03572 0.015 0.177745 0.000636 -0.379999 3.13988</pose>
          <geometry>
            <mesh>
              <scale>0.001 0.001 0.001</scale>
              <uri>/home/kamil/selfie/carolocup/src/Simulation/gazebo_selfie_sim/vehicles/sensors/camera/meshes/Basler.STL</uri>
            </mesh>
          </geometry>
          <material>
            <script>
              <name>Gazebo/DarkGray</name>
              <uri>file://media/materials/scripts/gazebo.material</uri>
            </script>
          </material>
        </visual>
        <visual name='selfie2021_fixed_joint_lump__depth_camera_link_visual_3'>
          <pose>0 0 0.1 3.14159 -1.57079 3.14159</pose>
          <geometry>
            <cylinder>
              <length>0.025</length>
              <radius>0.03</radius>
            </cylinder>
          </geometry>
          <material>
            <script>
              <name>Gazebo/DarkGray</name>
              <uri>file://media/materials/scripts/gazebo.material</uri>
            </script>
          </material>
        </visual>
        <visual name='selfie2021_fixed_joint_lump__left_back_indicator_visual_4'>
          <pose>-0.04 0.04 0.01 -1.5708 0 0</pose>
          <geometry>
            <cylinder>
              <length>0.019</length>
              <radius>0.01</radius>
            </cylinder>
          </geometry>
          <plugin name='indicator' filename='libIndicatorPlugin.so'>
            <on_color>1 0.6 0 1</on_color>
            <off_color>0 0 0 1</off_color>
            <topic>sim_left_turn_indicator</topic>
            <period>1</period>
            <robotNamespace>/</robotNamespace>
          </plugin>
          <material>
            <script>
              <name>Gazebo/Orange</name>
              <uri>file://media/materials/scripts/gazebo.material</uri>
            </script>
          </material>
        </visual>
        <visual name='selfie2021_fixed_joint_lump__left_front_indicator_visual_5'>
          <pose>0.26 0.04 0.01 -1.5708 0 0</pose>
          <geometry>
            <cylinder>
              <length>0.019</length>
              <radius>0.01</radius>
            </cylinder>
          </geometry>
          <plugin name='indicator' filename='libIndicatorPlugin.so'>
            <on_color>1 0.6 0 1</on_color>
            <off_color>0 0 0 1</off_color>
            <topic>sim_left_turn_indicator</topic>
            <period>1</period>
            <robotNamespace>/</robotNamespace>
          </plugin>
          <material>
            <script>
              <name>Gazebo/Orange</name>
              <uri>file://media/materials/scripts/gazebo.material</uri>
            </script>
          </material>
        </visual>
        <visual name='selfie2021_fixed_joint_lump__right_back_indicator_visual_6'>
          <pose>-0.04 -0.04 0.01 -1.5708 0 0</pose>
          <geometry>
            <cylinder>
              <length>0.019</length>
              <radius>0.01</radius>
            </cylinder>
          </geometry>
          <plugin name='indicator' filename='libIndicatorPlugin.so'>
            <on_color>1 0.6 0 1</on_color>
            <off_color>0 0 0 1</off_color>
            <topic>sim_right_turn_indicator</topic>
            <period>1</period>
            <robotNamespace>/</robotNamespace>
          </plugin>
          <material>
            <script>
              <name>Gazebo/Orange</name>
              <uri>file://media/materials/scripts/gazebo.material</uri>
            </script>
          </material>
        </visual>
        <visual name='selfie2021_fixed_joint_lump__right_front_indicator_visual_7'>
          <pose>0.26 -0.04 0.01 -1.5708 0 0</pose>
          <geometry>
            <cylinder>
              <length>0.019</length>
              <radius>0.01</radius>
            </cylinder>
          </geometry>
          <plugin name='indicator' filename='libIndicatorPlugin.so'>
            <on_color>1 0.6 0 1</on_color>
            <off_color>0 0 0 1</off_color>
            <topic>sim_right_turn_indicator</topic>
            <period>1</period>
            <robotNamespace>/</robotNamespace>
          </plugin>
          <material>
            <script>
              <name>Gazebo/Orange</name>
              <uri>file://media/materials/scripts/gazebo.material</uri>
            </script>
          </material>
        </visual>
        <velocity_decay/>
        <velocity_decay/>
        <velocity_decay/>
        <velocity_decay/>
        <sensor name='camera_sensor' type='camera'>
          <update_rate>100</update_rate>
          <camera name='main_camera'>
            <horizontal_fov>1.58</horizontal_fov>
            <image>
              <width>1024</width>
              <height>400</height>
              <format>L8</format>
            </image>
            <clip>
              <near>0.02</near>
              <far>300</far>
            </clip>
            <noise>
              <type>gaussian</type>
              <mean>0</mean>
              <stddev>0.007</stddev>
            </noise>
          </camera>
          <plugin name='camera_controller' filename='libgazebo_ros_camera.so'>
            <alwaysOn>1</alwaysOn>
            <updateRate>70</updateRate>
            <cameraName>/camera/zed</cameraName>
            <imageTopicName>/camera_basler/image_rect</imageTopicName>
            <cameraInfoTopicName>/camera_basler/camera_info</cameraInfoTopicName>
            <frameName>lens_link</frameName>
            <hackBaseline>0</hackBaseline>
            <distortionK1>0.0</distortionK1>
            <distortionK2>0.0</distortionK2>
            <distortionK3>0.0</distortionK3>
            <distortionT1>0.0</distortionT1>
            <robotNamespace>/</robotNamespace>
          </plugin>
          <pose>0.017147 0 0.185163 0 0.38 0</pose>
        </sensor>
        <velocity_decay/>
        <velocity_decay/>
        <sensor name='camera' type='depth'>
          <update_rate>20</update_rate>
          <camera>
            <horizontal_fov>1.0472</horizontal_fov>
            <image>
              <width>640</width>
              <height>480</height>
              <format>R8G8B8</format>
            </image>
            <clip>
              <near>0.05</near>
              <far>3</far>
            </clip>
          </camera>
          <plugin name='kinect_camera_controller' filename='libgazebo_ros_openni_kinect.so'>
            <cameraName>Intel_RealSense_LiDAR_Camera_L515</cameraName>
            <alwaysOn>1</alwaysOn>
            <updateRate>10</updateRate>
            <imageTopicName>/depth_camera/rgb/image_raw</imageTopicName>
            <depthImageTopicName>/depth_camera/depth/image_raw</depthImageTopicName>
            <pointCloudTopicName>/depth_camera/depth/points</pointCloudTopicName>
            <cameraInfoTopicName>/depth_camera/rgb/camera_info</cameraInfoTopicName>
            <depthImageCameraInfoTopicName>/depth_camera/depth/camera_info</depthImageCameraInfoTopicName>
            <frameName>depth_camera_lens_optical</frameName>
            <baseline>0.1</baseline>
            <distortion_k1>0.0</distortion_k1>
            <distortion_k2>0.0</distortion_k2>
            <distortion_k3>0.0</distortion_k3>
            <distortion_t1>0.0</distortion_t1>
            <distortion_t2>0.0</distortion_t2>
            <pointCloudCutoff>0.4</pointCloudCutoff>
            <robotNamespace>/</robotNamespace>
          </plugin>
          <pose>-0.03 0 0.100024 0 -0 0</pose>
        </sensor>
        <velocity_decay/>
        <sensor name='distance_sensor' type='ray'>
          <visualize>0</visualize>
          <update_rate>100</update_rate>
          <ray>
            <scan>
              <horizontal>
                <samples>1</samples>
                <resolution>1</resolution>
                <min_angle>0</min_angle>
                <max_angle>0.1</max_angle>
              </horizontal>
              <vertical>
                <samples>1</samples>
                <min_angle>0</min_angle>
                <max_angle>0</max_angle>
              </vertical>
            </scan>
            <range>
              <min>0.01</min>
              <max>5</max>
              <resolution>0.005</resolution>
            </range>
            <noise>
              <type>gaussian</type>
              <mean>0</mean>
              <stddev>0.001</stddev>
            </noise>
          </ray>
          <plugin name='gazebo_ros_head_hokuyo_controller' filename='libgazebo_ros_laser.so'>
            <topicName>/vehicle/back_distance</topicName>
            <frameName>base_link</frameName>
            <robotNamespace>/</robotNamespace>
          </plugin>
          <pose>0 -0.11 0 0 0 -1.57</pose>
        </sensor>
        <velocity_decay/>
        <sensor name='imu_sensor' type='imu'>
          <always_on>1</always_on>
          <update_rate>100</update_rate>
          <visualize>0</visualize>
          <topic>__default_topic__</topic>
          <plugin name='imu_plugin' filename='libgazebo_ros_imu_sensor.so'>
            <topicName>imu</topicName>
            <bodyName>imu_link</bodyName>
            <updateRateHZ>100.0</updateRateHZ>
            <gaussianNoise>0.0</gaussianNoise>
            <xyzOffset>0 0 0</xyzOffset>
            <rpyOffset>0 0 0</rpyOffset>
            <frameName>imu_link</frameName>
            <initialOrientationAsReference>0</initialOrientationAsReference>
            <robotNamespace>/</robotNamespace>
          </plugin>
          <pose>0.15 0 0 0 -0 0</pose>
          <imu/>
        </sensor>
        <velocity_decay/>
        <velocity_decay/>
        <gravity>1</gravity>
        <velocity_decay/>
        <gravity>1</gravity>
        <velocity_decay/>
        <self_collide>0</self_collide>
        <enable_wind>0</enable_wind>
        <kinematic>0</kinematic>
      </link>
      <joint name='left_front_steering_hinge_joint' type='revolute'>
        <pose relative_to='selfie2021'>0.22 0.1 0 0 -0 0</pose>
        <parent>selfie2021</parent>
        <child>left_front_steering_hinge</child>
        <axis>
          <xyz>0 0 1</xyz>
          <limit>
            <lower>-1</lower>
            <upper>1</upper>
            <effort>10000</effort>
            <velocity>1000</velocity>
          </limit>
          <dynamics>
            <spring_reference>0</spring_reference>
            <spring_stiffness>0</spring_stiffness>
          </dynamics>
        </axis>
      </joint>
      <link name='left_front_steering_hinge'>
        <pose relative_to='left_front_steering_hinge_joint'>0 0 0 0 -0 0</pose>
        <inertial>
          <pose>0 0 0 0 -0 0</pose>
          <mass>1</mass>
          <inertia>
            <ixx>0.00666667</ixx>
            <ixy>0</ixy>
            <ixz>0</ixz>
            <iyy>0.00666667</iyy>
            <iyz>0</iyz>
            <izz>0.00666667</izz>
          </inertia>
        </inertial>
        <self_collide>0</self_collide>
        <enable_wind>0</enable_wind>
        <kinematic>0</kinematic>
      </link>
      <joint name='left_front_wheel_joint' type='revolute'>
        <pose relative_to='left_front_steering_hinge'>0 0 0 0 -0 0</pose>
        <parent>left_front_steering_hinge</parent>
        <child>left_front_wheel</child>
        <axis>
          <xyz>0 1 0</xyz>
          <limit>
            <lower>-1e+16</lower>
            <upper>1e+16</upper>
          </limit>
          <dynamics>
            <spring_reference>0</spring_reference>
            <spring_stiffness>0</spring_stiffness>
          </dynamics>
        </axis>
      </joint>
      <link name='left_front_wheel'>
        <pose relative_to='left_front_wheel_joint'>0 0 0 0 -0 0</pose>
        <inertial>
          <pose>0 0 0 0 -0 0</pose>
          <mass>10</mass>
          <inertia>
            <ixx>0.00475</ixx>
            <ixy>0</ixy>
            <ixz>0</ixz>
            <iyy>0.00475</iyy>
            <iyz>0</iyz>
            <izz>0.008</izz>
          </inertia>
        </inertial>
        <collision name='left_front_wheel_collision'>
          <pose>0 0 0 -1.5708 0 0</pose>
          <geometry>
            <cylinder>
              <length>0.03</length>
              <radius>0.04</radius>
            </cylinder>
          </geometry>
          <surface>
            <contact>
              <ode>
                <kp>1e+07</kp>
                <kd>1</kd>
              </ode>
            </contact>
            <friction>
              <ode>
                <mu>1</mu>
                <mu2>1</mu2>
              </ode>
              <torsional>
                <ode/>
              </torsional>
            </friction>
            <bounce/>
          </surface>
          <max_contacts>10</max_contacts>
        </collision>
        <visual name='left_front_wheel_visual'>
          <pose>0 0 0 -1.5708 0 0</pose>
          <geometry>
            <cylinder>
              <length>0.03</length>
              <radius>0.04</radius>
            </cylinder>
          </geometry>
          <material>
            <script>
              <name>Gazebo/DarkGray</name>
              <uri>file://media/materials/scripts/gazebo.material</uri>
            </script>
          </material>
        </visual>
        <gravity>1</gravity>
        <velocity_decay/>
        <self_collide>0</self_collide>
        <enable_wind>0</enable_wind>
        <kinematic>0</kinematic>
        <dynamics>
          <damping>0.7</damping>
        </dynamics>
      </link>
      <joint name='left_rear_steering_hinge_joint' type='revolute'>
        <pose relative_to='selfie2021'>0 0.1 0 0 -0 0</pose>
        <parent>selfie2021</parent>
        <child>left_rear_steering_hinge</child>
        <axis>
          <xyz>0 0 1</xyz>
          <limit>
            <lower>-1</lower>
            <upper>1</upper>
            <effort>10000</effort>
            <velocity>1000</velocity>
          </limit>
          <dynamics>
            <spring_reference>0</spring_reference>
            <spring_stiffness>0</spring_stiffness>
          </dynamics>
        </axis>
      </joint>
      <link name='left_rear_steering_hinge'>
        <pose relative_to='left_rear_steering_hinge_joint'>0 0 0 0 -0 0</pose>
        <inertial>
          <pose>0 0 0 0 -0 0</pose>
          <mass>1</mass>
          <inertia>
            <ixx>0.00666667</ixx>
            <ixy>0</ixy>
            <ixz>0</ixz>
            <iyy>0.00666667</iyy>
            <iyz>0</iyz>
            <izz>0.00666667</izz>
          </inertia>
        </inertial>
        <self_collide>0</self_collide>
        <enable_wind>0</enable_wind>
        <kinematic>0</kinematic>
      </link>
      <joint name='left_rear_wheel_joint' type='revolute'>
        <pose relative_to='left_rear_steering_hinge'>0 0 0 0 -0 0</pose>
        <parent>left_rear_steering_hinge</parent>
        <child>left_rear_wheel</child>
        <axis>
          <xyz>0 1 0</xyz>
          <limit>
            <lower>-1e+16</lower>
            <upper>1e+16</upper>
          </limit>
          <dynamics>
            <spring_reference>0</spring_reference>
            <spring_stiffness>0</spring_stiffness>
          </dynamics>
        </axis>
      </joint>
      <link name='left_rear_wheel'>
        <pose relative_to='left_rear_wheel_joint'>0 0 0 0 -0 0</pose>
        <inertial>
          <pose>0 0 0 0 -0 0</pose>
          <mass>10</mass>
          <inertia>
            <ixx>0.00475</ixx>
            <ixy>0</ixy>
            <ixz>0</ixz>
            <iyy>0.00475</iyy>
            <iyz>0</iyz>
            <izz>0.008</izz>
          </inertia>
        </inertial>
        <collision name='left_rear_wheel_collision'>
          <pose>0 0 0 -1.5708 0 0</pose>
          <geometry>
            <cylinder>
              <length>0.03</length>
              <radius>0.04</radius>
            </cylinder>
          </geometry>
          <surface>
            <contact>
              <ode>
                <kp>1e+07</kp>
                <kd>1</kd>
              </ode>
            </contact>
            <friction>
              <ode>
                <mu>1</mu>
                <mu2>1</mu2>
              </ode>
              <torsional>
                <ode/>
              </torsional>
            </friction>
            <bounce/>
          </surface>
          <max_contacts>10</max_contacts>
        </collision>
        <visual name='left_rear_wheel_visual'>
          <pose>0 0 0 -1.5708 0 0</pose>
          <geometry>
            <cylinder>
              <length>0.03</length>
              <radius>0.04</radius>
            </cylinder>
          </geometry>
          <material>
            <script>
              <name>Gazebo/DarkGray</name>
              <uri>file://media/materials/scripts/gazebo.material</uri>
            </script>
          </material>
        </visual>
        <gravity>1</gravity>
        <velocity_decay/>
        <self_collide>0</self_collide>
        <enable_wind>0</enable_wind>
        <kinematic>0</kinematic>
        <dynamics>
          <damping>0.7</damping>
        </dynamics>
      </link>
      <joint name='right_front_steering_hinge_joint' type='revolute'>
        <pose relative_to='selfie2021'>0.22 -0.1 0 0 -0 0</pose>
        <parent>selfie2021</parent>
        <child>right_front_steering_hinge</child>
        <axis>
          <xyz>0 0 1</xyz>
          <limit>
            <lower>-1</lower>
            <upper>1</upper>
            <effort>10000</effort>
            <velocity>1000</velocity>
          </limit>
          <dynamics>
            <spring_reference>0</spring_reference>
            <spring_stiffness>0</spring_stiffness>
          </dynamics>
        </axis>
      </joint>
      <link name='right_front_steering_hinge'>
        <pose relative_to='right_front_steering_hinge_joint'>0 0 0 0 -0 0</pose>
        <inertial>
          <pose>0 0 0 0 -0 0</pose>
          <mass>1</mass>
          <inertia>
            <ixx>0.00666667</ixx>
            <ixy>0</ixy>
            <ixz>0</ixz>
            <iyy>0.00666667</iyy>
            <iyz>0</iyz>
            <izz>0.00666667</izz>
          </inertia>
        </inertial>
        <self_collide>0</self_collide>
        <enable_wind>0</enable_wind>
        <kinematic>0</kinematic>
      </link>
      <joint name='right_front_wheel_joint' type='revolute'>
        <pose relative_to='right_front_steering_hinge'>0 0 0 0 -0 0</pose>
        <parent>right_front_steering_hinge</parent>
        <child>right_front_wheel</child>
        <axis>
          <xyz>0 1 0</xyz>
          <limit>
            <lower>-1e+16</lower>
            <upper>1e+16</upper>
          </limit>
          <dynamics>
            <spring_reference>0</spring_reference>
            <spring_stiffness>0</spring_stiffness>
          </dynamics>
        </axis>
      </joint>
      <link name='right_front_wheel'>
        <pose relative_to='right_front_wheel_joint'>0 0 0 0 -0 0</pose>
        <inertial>
          <pose>0 0 0 0 -0 0</pose>
          <mass>10</mass>
          <inertia>
            <ixx>0.00475</ixx>
            <ixy>0</ixy>
            <ixz>0</ixz>
            <iyy>0.00475</iyy>
            <iyz>0</iyz>
            <izz>0.008</izz>
          </inertia>
        </inertial>
        <collision name='right_front_wheel_collision'>
          <pose>0 0 0 -1.5708 0 0</pose>
          <geometry>
            <cylinder>
              <length>0.03</length>
              <radius>0.04</radius>
            </cylinder>
          </geometry>
          <surface>
            <contact>
              <ode>
                <kp>1e+07</kp>
                <kd>1</kd>
              </ode>
            </contact>
            <friction>
              <ode>
                <mu>1</mu>
                <mu2>1</mu2>
              </ode>
              <torsional>
                <ode/>
              </torsional>
            </friction>
            <bounce/>
          </surface>
          <max_contacts>10</max_contacts>
        </collision>
        <visual name='right_front_wheel_visual'>
          <pose>0 0 0 -1.5708 0 0</pose>
          <geometry>
            <cylinder>
              <length>0.03</length>
              <radius>0.04</radius>
            </cylinder>
          </geometry>
          <material>
            <script>
              <name>Gazebo/DarkGray</name>
              <uri>file://media/materials/scripts/gazebo.material</uri>
            </script>
          </material>
        </visual>
        <gravity>1</gravity>
        <velocity_decay/>
        <self_collide>0</self_collide>
        <enable_wind>0</enable_wind>
        <kinematic>0</kinematic>
        <dynamics>
          <damping>0.7</damping>
        </dynamics>
      </link>
      <joint name='right_rear_steering_hinge_joint' type='revolute'>
        <pose relative_to='selfie2021'>0 -0.1 0 0 -0 0</pose>
        <parent>selfie2021</parent>
        <child>right_rear_steering_hinge</child>
        <axis>
          <xyz>0 0 1</xyz>
          <limit>
            <lower>-1</lower>
            <upper>1</upper>
            <effort>10000</effort>
            <velocity>1000</velocity>
          </limit>
          <dynamics>
            <spring_reference>0</spring_reference>
            <spring_stiffness>0</spring_stiffness>
          </dynamics>
        </axis>
      </joint>
      <link name='right_rear_steering_hinge'>
        <pose relative_to='right_rear_steering_hinge_joint'>0 0 0 0 -0 0</pose>
        <inertial>
          <pose>0 0 0 0 -0 0</pose>
          <mass>1</mass>
          <inertia>
            <ixx>0.00666667</ixx>
            <ixy>0</ixy>
            <ixz>0</ixz>
            <iyy>0.00666667</iyy>
            <iyz>0</iyz>
            <izz>0.00666667</izz>
          </inertia>
        </inertial>
        <self_collide>0</self_collide>
        <enable_wind>0</enable_wind>
        <kinematic>0</kinematic>
      </link>
      <joint name='right_rear_wheel_joint' type='revolute'>
        <pose relative_to='right_rear_steering_hinge'>0 0 0 0 -0 0</pose>
        <parent>right_rear_steering_hinge</parent>
        <child>right_rear_wheel</child>
        <axis>
          <xyz>0 1 0</xyz>
          <limit>
            <lower>-1e+16</lower>
            <upper>1e+16</upper>
          </limit>
          <dynamics>
            <spring_reference>0</spring_reference>
            <spring_stiffness>0</spring_stiffness>
          </dynamics>
        </axis>
      </joint>
      <link name='right_rear_wheel'>
        <pose relative_to='right_rear_wheel_joint'>0 0 0 0 -0 0</pose>
        <inertial>
          <pose>0 0 0 0 -0 0</pose>
          <mass>10</mass>
          <inertia>
            <ixx>0.00475</ixx>
            <ixy>0</ixy>
            <ixz>0</ixz>
            <iyy>0.00475</iyy>
            <iyz>0</iyz>
            <izz>0.008</izz>
          </inertia>
        </inertial>
        <collision name='right_rear_wheel_collision'>
          <pose>0 0 0 -1.5708 0 0</pose>
          <geometry>
            <cylinder>
              <length>0.03</length>
              <radius>0.04</radius>
            </cylinder>
          </geometry>
          <surface>
            <contact>
              <ode>
                <kp>1e+07</kp>
                <kd>1</kd>
              </ode>
            </contact>
            <friction>
              <ode>
                <mu>1</mu>
                <mu2>1</mu2>
              </ode>
              <torsional>
                <ode/>
              </torsional>
            </friction>
            <bounce/>
          </surface>
          <max_contacts>10</max_contacts>
        </collision>
        <visual name='right_rear_wheel_visual'>
          <pose>0 0 0 -1.5708 0 0</pose>
          <geometry>
            <cylinder>
              <length>0.03</length>
              <radius>0.04</radius>
            </cylinder>
          </geometry>
          <material>
            <script>
              <name>Gazebo/DarkGray</name>
              <uri>file://media/materials/scripts/gazebo.material</uri>
            </script>
          </material>
        </visual>
        <gravity>1</gravity>
        <velocity_decay/>
        <self_collide>0</self_collide>
        <enable_wind>0</enable_wind>
        <kinematic>0</kinematic>
        <dynamics>
          <damping>0.7</damping>
        </dynamics>
      </link>
      <static>0</static>
      <plugin name='gazebo_ros_control' filename='libgazebo_ros_control.so'>
        <robotNamespace>/vehicle</robotNamespace>
        <robotSimType>gazebo_ros_control/DefaultRobotHWSim</robotSimType>
        <legacyModeNS>1</legacyModeNS>
      </plugin>
      <pose>0 0 0.2 0 -0 0</pose>
    </model>
    <model name='Parking_zone'>
      <pose>1.98924 -0.282898 0 0 -0 0</pose>
      <static>1</static>
      <link name='body'>
        <visual name='visual'>
          <geometry>
            <mesh>
              <uri>model://meshes/Parking_zone.dae</uri>
              <scale>1 1 1</scale>
            </mesh>
          </geometry>
        </visual>
        <self_collide>0</self_collide>
        <enable_wind>0</enable_wind>
        <kinematic>0</kinematic>
      </link>
    </model>
    <light name='sun' type='directional'>
      <cast_shadows>1</cast_shadows>
      <pose>9.95372 2.97949 10 0 -0 0</pose>
      <diffuse>0.8 0.8 0.8 1</diffuse>
      <specular>0.2 0.2 0.2 1</specular>
      <attenuation>
        <range>1000</range>
        <constant>0.9</constant>
        <linear>0.01</linear>
        <quadratic>0.001</quadratic>
      </attenuation>
      <direction>-0.5 0.1 -0.9</direction>
      <spot>
        <inner_angle>0</inner_angle>
        <outer_angle>0</outer_angle>
        <falloff>0</falloff>
      </spot>
    </light>
    <light name='user_point_light_0' type='point'>
      <pose>1.26925 1.02698 1 0 -0 0</pose>
      <diffuse>0.5 0.5 0.5 1</diffuse>
      <specular>0.1 0.1 0.1 1</specular>
      <attenuation>
        <range>20</range>
        <constant>0.5</constant>
        <linear>0.01</linear>
        <quadratic>0.001</quadratic>
      </attenuation>
      <cast_shadows>0</cast_shadows>
      <direction>0 0 -1</direction>
      <spot>
        <inner_angle>0</inner_angle>
        <outer_angle>0</outer_angle>
        <falloff>0</falloff>
      </spot>
    </light>
    <state world_name='cc22_track_v1'>
      <sim_time>4435 473000000</sim_time>
      <real_time>558 375052684</real_time>
      <wall_time>1631813311 213295748</wall_time>
      <iterations>538506</iterations>
      <model name='20_Zone'>
        <pose>5.63093 6.10252 0 0 -0 0.629469</pose>
        <scale>1 1 1</scale>
        <link name='body'>
          <pose>5.63093 6.10252 0 0 -0 0.629469</pose>
          <velocity>0 0 0 0 -0 0</velocity>
          <acceleration>0 0 0 0 -0 0</acceleration>
          <wrench>0 0 0 0 -0 0</wrench>
        </link>
      </model>
      <model name='20_Zone_End'>
        <pose>7.97543 6.30189 0 0 -0 2.3401</pose>
        <scale>1 1 1</scale>
        <link name='body'>
          <pose>7.97543 6.30189 0 0 -0 2.3401</pose>
          <velocity>0 0 0 0 -0 0</velocity>
          <acceleration>0 0 0 0 -0 0</acceleration>
          <wrench>0 0 0 0 -0 0</wrench>
        </link>
      </model>
      <model name='30_Zone'>
        <pose>14.8988 8.26058 0 0 -0 2.27141</pose>
        <scale>1 1 1</scale>
        <link name='body'>
          <pose>14.8988 8.26058 0 0 -0 2.27141</pose>
          <velocity>0 0 0 0 -0 0</velocity>
          <acceleration>0 0 0 0 -0 0</acceleration>
          <wrench>0 0 0 0 -0 0</wrench>
        </link>
      </model>
      <model name='30_Zone_End'>
        <pose>8.5452 3.03846 0 0 -0 1.2526</pose>
        <scale>1 1 1</scale>
        <link name='body'>
          <pose>8.5452 3.03846 0 0 -0 1.2526</pose>
          <velocity>0 0 0 0 -0 0</velocity>
          <acceleration>0 0 0 0 -0 0</acceleration>
          <wrench>0 0 0 0 -0 0</wrench>
        </link>
      </model>
      <model name='Barred_area'>
        <pose>5.09851 7.01412 0 0 0 -0.819991</pose>
        <scale>1 1 1</scale>
        <link name='body'>
          <pose>5.09851 7.01412 0 0 0 -0.819991</pose>
          <velocity>0 0 0 0 -0 0</velocity>
          <acceleration>0 0 0 0 -0 0</acceleration>
          <wrench>0 0 0 0 -0 0</wrench>
        </link>
      </model>
      <model name='Downhill_grade'>
        <pose>19.1046 4.09776 0.144093 0 -0 0</pose>
        <scale>1 1 1</scale>
        <link name='body'>
          <pose>19.1046 4.09776 0.144093 0 -0 0</pose>
          <velocity>0 0 0 0 -0 0</velocity>
          <acceleration>0 0 0 0 -0 0</acceleration>
          <wrench>0 0 0 0 -0 0</wrench>
        </link>
      </model>
      <model name='Expressway_end'>
        <pose>16.0311 -0.320557 0 0 0 -1.57548</pose>
        <scale>1 1 1</scale>
        <link name='body'>
          <pose>16.0311 -0.320557 0 0 0 -1.57548</pose>
          <velocity>0 0 0 0 -0 0</velocity>
          <acceleration>0 0 0 0 -0 0</acceleration>
          <wrench>0 0 0 0 -0 0</wrench>
        </link>
      </model>
      <model name='Give_way'>
        <pose>8.19203 7.06632 0 0 0 -2.39632</pose>
        <scale>1 1 1</scale>
        <link name='body'>
          <pose>8.19203 7.06632 0 0 0 -2.39632</pose>
          <velocity>0 0 0 0 -0 0</velocity>
          <acceleration>0 0 0 0 -0 0</acceleration>
          <wrench>0 0 0 0 -0 0</wrench>
        </link>
      </model>
      <model name='Left_turn'>
        <pose>14.2202 7.51193 0 0 -0 2.31464</pose>
        <scale>1 1 1</scale>
        <link name='body'>
          <pose>14.2202 7.51193 0 0 -0 2.31464</pose>
          <velocity>0 0 0 0 -0 0</velocity>
          <acceleration>0 0 0 0 -0 0</acceleration>
          <wrench>0 0 0 0 -0 0</wrench>
        </link>
      </model>
      <model name='No_passing_zone_beginning'>
        <pose>19.0864 6.77755 0 0 -0 0</pose>
        <scale>1 1 1</scale>
        <link name='body'>
          <pose>19.0864 6.77755 0 0 -0 0</pose>
          <velocity>0 0 0 0 -0 0</velocity>
          <acceleration>0 0 0 0 -0 0</acceleration>
          <wrench>0 0 0 0 -0 0</wrench>
        </link>
      </model>
      <model name='No_passing_zone_end'>
        <pose>14.9463 5.32498 0 0 0 -2.47578</pose>
        <scale>1 1 1</scale>
        <link name='body'>
          <pose>14.9463 5.32498 0 0 0 -2.47578</pose>
          <velocity>0 0 0 0 -0 0</velocity>
          <acceleration>0 0 0 0 -0 0</acceleration>
          <wrench>0 0 0 0 -0 0</wrench>
        </link>
      </model>
      <model name='Parking_zone'>
        <pose>1.98924 -0.282898 0 0 0 -1.55626</pose>
        <scale>1 1 1</scale>
        <link name='body'>
          <pose>1.98924 -0.282898 0 0 0 -1.55626</pose>
          <velocity>0 0 0 0 -0 0</velocity>
          <acceleration>0 0 0 0 -0 0</acceleration>
          <wrench>0 0 0 0 -0 0</wrench>
        </link>
      </model>
      <model name='Pedestrian_island'>
        <pose>10.8946 3.5613 0 0 -0 2.08591</pose>
        <scale>1 1 1</scale>
        <link name='body'>
          <pose>10.8946 3.5613 0 0 -0 2.08591</pose>
          <velocity>0 0 0 0 -0 0</velocity>
          <acceleration>0 0 0 0 -0 0</acceleration>
          <wrench>0 0 0 0 -0 0</wrench>
        </link>
      </model>
      <model name='Preference'>
        <pose>14.3654 7.66537 0 0 -0 2.30628</pose>
        <scale>1 1 1</scale>
        <link name='body'>
          <pose>14.3654 7.66537 0 0 -0 2.30628</pose>
          <velocity>0 0 0 0 -0 0</velocity>
          <acceleration>0 0 0 0 -0 0</acceleration>
          <wrench>0 0 0 0 -0 0</wrench>
        </link>
      </model>
      <model name='Preference_0'>
        <pose>6.63736 4.93916 0 0 -0 2.28536</pose>
        <scale>1 1 1</scale>
        <link name='body'>
          <pose>6.63736 4.93916 0 0 -0 2.28536</pose>
          <velocity>0 0 0 0 -0 0</velocity>
          <acceleration>0 0 0 0 -0 0</acceleration>
          <wrench>0 0 0 0 -0 0</wrench>
        </link>
      </model>
      <model name='Ramp'>
        <pose>18.4114 4.22846 -0.017757 0 0 -1.57058</pose>
        <scale>1 1 1</scale>
        <link name='body'>
          <pose>18.4114 4.22846 -0.017757 0 0 -1.57058</pose>
          <velocity>0 0 0 0 -0 0</velocity>
          <acceleration>0 0 0 0 -0 0</acceleration>
          <wrench>0 0 0 0 -0 0</wrench>
        </link>
      </model>
      <model name='Right_turn'>
        <pose>4.99618 6.67416 0 0 -0 0.65564</pose>
        <scale>1 1 1</scale>
        <link name='body'>
          <pose>4.99618 6.67416 0 0 -0 0.65564</pose>
          <velocity>0 0 0 0 -0 0</velocity>
          <acceleration>0 0 0 0 -0 0</acceleration>
          <wrench>0 0 0 0 -0 0</wrench>
        </link>
      </model>
      <model name='Right_turn_0'>
        <pose>8.36332 6.91755 0 0 0 -2.41142</pose>
        <scale>1 1 1</scale>
        <link name='body'>
          <pose>8.36332 6.91755 0 0 0 -2.41142</pose>
          <velocity>0 0 0 0 -0 0</velocity>
          <acceleration>0 0 0 0 -0 0</acceleration>
          <wrench>0 0 0 0 -0 0</wrench>
        </link>
      </model>
      <model name='Sharp_turn_left_long_2_legs'>
        <pose>15.6003 -0.384251 0 0 0 -1.597</pose>
        <scale>1 1 1</scale>
        <link name='body'>
          <pose>15.6003 -0.384251 0 0 0 -1.597</pose>
          <velocity>0 0 0 0 -0 0</velocity>
          <acceleration>0 0 0 0 -0 0</acceleration>
          <wrench>0 0 0 0 -0 0</wrench>
        </link>
      </model>
      <model name='Sharp_turn_left_long_2_legs_clone'>
        <pose>16.8885 -0.394299 0 0 0 -1.53922</pose>
        <scale>1 1 1</scale>
        <link name='body'>
          <pose>16.8885 -0.394299 0 0 0 -1.53922</pose>
          <velocity>0 0 0 0 -0 0</velocity>
          <acceleration>0 0 0 0 -0 0</acceleration>
          <wrench>0 0 0 0 -0 0</wrench>
        </link>
      </model>
      <model name='Sharp_turn_left_short'>
        <pose>17.3687 -0.271797 0 0 0 -1.59471</pose>
        <scale>1 1 1</scale>
        <link name='body'>
          <pose>17.3687 -0.271797 0 0 0 -1.59471</pose>
          <velocity>0 0 0 0 -0 0</velocity>
          <acceleration>0 0 0 0 -0 0</acceleration>
          <wrench>0 0 0 0 -0 0</wrench>
        </link>
      </model>
      <model name='Sharp_turn_left_short_clone'>
        <pose>17.6963 -0.166184 0 0 0 -1.59471</pose>
        <scale>1 1 1</scale>
        <link name='body'>
          <pose>17.6963 -0.166184 0 0 0 -1.59471</pose>
          <velocity>0 0 0 0 -0 0</velocity>
          <acceleration>0 0 0 0 -0 0</acceleration>
          <wrench>0 0 0 0 -0 0</wrench>
        </link>
      </model>
      <model name='Sharp_turn_left_short_clone_0'>
        <pose>18.0158 -0.018092 0 0 0 -1.59471</pose>
        <scale>1 1 1</scale>
        <link name='body'>
          <pose>18.0158 -0.018092 0 0 0 -1.59471</pose>
          <velocity>0 0 0 0 -0 0</velocity>
          <acceleration>0 0 0 0 -0 0</acceleration>
          <wrench>0 0 0 0 -0 0</wrench>
        </link>
      </model>
      <model name='Sharp_turn_left_short_clone_1'>
        <pose>18.2577 0.162746 0 0 0 -1.59471</pose>
        <scale>1 1 1</scale>
        <link name='body'>
          <pose>18.2577 0.162746 0 0 0 -1.59471</pose>
          <velocity>0 0 0 0 -0 0</velocity>
          <acceleration>0 0 0 0 -0 0</acceleration>
          <wrench>0 0 0 0 -0 0</wrench>
        </link>
      </model>
      <model name='Sharp_turn_left_short_clone_2'>
        <pose>18.5106 0.401209 0 0 0 -1.50149</pose>
        <scale>1 1 1</scale>
        <link name='body'>
          <pose>18.5106 0.401209 0 0 0 -1.50149</pose>
          <velocity>0 0 0 0 -0 0</velocity>
          <acceleration>0 0 0 0 -0 0</acceleration>
          <wrench>0 0 0 0 -0 0</wrench>
        </link>
      </model>
      <model name='Sharp_turn_left_short_clone_3'>
        <pose>18.7112 0.644653 0 0 0 -1.4379</pose>
        <scale>1 1 1</scale>
        <link name='body'>
          <pose>18.7112 0.644653 0 0 0 -1.4379</pose>
          <velocity>0 0 0 0 -0 0</velocity>
          <acceleration>0 0 0 0 -0 0</acceleration>
          <wrench>0 0 0 0 -0 0</wrench>
        </link>
      </model>
      <model name='Sharp_turn_left_short_clone_4'>
        <pose>18.8634 0.898232 0 0 0 -1.38852</pose>
        <scale>1 1 1</scale>
        <link name='body'>
          <pose>18.8634 0.898232 0 0 0 -1.38852</pose>
          <velocity>0 0 0 0 -0 0</velocity>
          <acceleration>0 0 0 0 -0 0</acceleration>
          <wrench>0 0 0 0 -0 0</wrench>
        </link>
      </model>
      <model name='Stop'>
        <pose>7.40622 3.93788 0 0 -0 0.707659</pose>
        <scale>1 1 1</scale>
        <link name='body'>
          <pose>7.40622 3.93788 0 0 -0 0.707659</pose>
          <velocity>0 0 0 0 -0 0</velocity>
          <acceleration>0 0 0 0 -0 0</acceleration>
          <wrench>0 0 0 0 -0 0</wrench>
        </link>
      </model>
      <model name='Stop_0'>
        <pose>5.17796 6.51667 0 0 -0 0.75532</pose>
        <scale>1 1 1</scale>
        <link name='body'>
          <pose>5.17796 6.51667 0 0 -0 0.75532</pose>
          <velocity>0 0 0 0 -0 0</velocity>
          <acceleration>0 0 0 0 -0 0</acceleration>
          <wrench>0 0 0 0 -0 0</wrench>
        </link>
      </model>
      <model name='Uphill_grade'>
        <pose>19.0243 1.41754 0 0 0 -0.221037</pose>
        <scale>1 1 1</scale>
        <link name='body'>
          <pose>19.0243 1.41754 0 0 0 -0.221037</pose>
          <velocity>0 0 0 0 -0 0</velocity>
          <acceleration>0 0 0 0 -0 0</acceleration>
          <wrench>0 0 0 0 -0 0</wrench>
        </link>
      </model>
      <model name='Zebra_crossing'>
        <pose>6.26236 8.03524 0 0 0 -1.74218</pose>
        <scale>1 1 1</scale>
        <link name='body'>
          <pose>6.26236 8.03524 0 0 0 -1.74218</pose>
          <velocity>0 0 0 0 -0 0</velocity>
          <acceleration>0 0 0 0 -0 0</acceleration>
          <wrench>0 0 0 0 -0 0</wrench>
        </link>
      </model>
      <model name='robot'>
        <pose>-0.200317 9e-06 0.039968 0 -4e-06 0</pose>
        <scale>1 1 1</scale>
        <link name='left_front_steering_hinge'>
          <pose>0.019683 0.100009 0.039969 0 -4e-06 -9e-06</pose>
          <velocity>-4.5e-05 -2e-06 -0.007463 2.7e-05 -0.00111 0</velocity>
          <acceleration>-0.000218 7.2e-05 7e-06 -0.000785 -2e-06 0.000142</acceleration>
          <wrench>-0.000218 7.2e-05 7e-06 0 -0 0</wrench>
        </link>
        <link name='left_front_wheel'>
          <pose>0.019683 0.100009 0.039969 -3e-06 1.27527 -1.1e-05</pose>
          <velocity>-4.5e-05 -3e-06 -0.007459 6.8e-05 -0.001119 -5e-06</velocity>
          <acceleration>-0.000205 7.8e-05 6e-06 -0.001264 -0.005119 0.000541</acceleration>
          <wrench>-0.002053 0.000782 6.2e-05 0 -0 0</wrench>
        </link>
        <link name='left_rear_steering_hinge'>
          <pose>-0.200317 0.100009 0.039968 0 -4e-06 0</pose>
          <velocity>-4.5e-05 -3e-06 -0.007719 3.3e-05 -0.001113 -0.000161</velocity>
          <acceleration>-0.00026 -9e-05 6e-06 0.000319 -1e-06 -0.187919</acceleration>
          <wrench>-0.00026 -9e-05 6e-06 0 -0 0</wrench>
        </link>
        <link name='left_rear_wheel'>
          <pose>-0.200317 0.100009 0.039968 -4e-06 1.27527 -3e-06</pose>
          <velocity>-4.5e-05 -3e-06 -0.007712 7.4e-05 -0.001127 -7.6e-05</velocity>
          <acceleration>-0.000291 4.3e-05 5e-06 0.014796 -0.0129 -0.138359</acceleration>
          <wrench>-0.002906 0.000426 4.5e-05 0 -0 0</wrench>
        </link>
        <link name='right_front_steering_hinge'>
          <pose>0.019683 -0.099991 0.039969 -1e-06 -4e-06 4e-06</pose>
          <velocity>-4.4e-05 -3e-06 -0.007475 3.8e-05 -0.001108 1.7e-05</velocity>
          <acceleration>0.000249 7.3e-05 -8e-06 -0.000788 -2e-06 2.4e-05</acceleration>
          <wrench>0.000249 7.3e-05 -8e-06 0 -0 0</wrench>
        </link>
        <link name='right_front_wheel'>
          <pose>0.019683 -0.099991 0.039969 -4e-06 1.27526 0</pose>
          <velocity>-4.4e-05 -3e-06 -0.007469 7.9e-05 -0.001103 3e-06</velocity>
          <acceleration>0.000235 7.9e-05 -6e-06 -0.001264 0.005872 0.000444</acceleration>
          <wrench>0.002345 0.000789 -6.4e-05 0 -0 0</wrench>
        </link>
        <link name='right_rear_steering_hinge'>
          <pose>-0.200317 -0.099991 0.039968 0 -4e-06 0</pose>
          <velocity>-4.4e-05 -9e-06 -0.00769 -6e-06 -0.001113 1e-05</velocity>
          <acceleration>0.000178 -0.000255 0 -0.000263 -3e-06 0.000471</acceleration>
          <wrench>0.000178 -0.000255 0 0 -0 0</wrench>
        </link>
        <link name='right_rear_wheel'>
          <pose>-0.200317 -0.099991 0.039968 -4e-06 1.27525 -3e-06</pose>
          <velocity>-4.4e-05 -3e-06 -0.007701 8.2e-05 -0.0011 -1e-06</velocity>
          <acceleration>0.000241 -9.5e-05 -5e-06 0.00149 0.006016 -0.000235</acceleration>
          <wrench>0.002406 -0.000952 -4.6e-05 0 -0 0</wrench>
        </link>
        <link name='selfie2021'>
          <pose>-0.200317 9e-06 0.039968 0 -4e-06 0</pose>
          <velocity>-4.4e-05 -7e-06 -0.007694 1e-06 -0.00111 3e-06</velocity>
          <acceleration>1e-05 -1.7e-05 0 6e-06 -2e-06 0.001806</acceleration>
          <wrench>0.000969 -0.001706 7e-06 0 -0 0</wrench>
        </link>
      </model>
      <model name='track'>
        <pose>9.19 4.29 0 0 -0 0</pose>
        <scale>1 1 1</scale>
        <link name='track'>
          <pose>9.19 4.29 0 0 -0 0</pose>
          <velocity>0 0 0 0 -0 0</velocity>
          <acceleration>0 0 0 0 -0 0</acceleration>
          <wrench>0 0 0 0 -0 0</wrench>
        </link>
      </model>
      <light name='sun'>
        <pose>9.95372 2.97949 10 0 -0 0</pose>
      </light>
      <light name='user_point_light_0'>
        <pose>-2.17267 -0.46875 -12.9837 0 -0 0</pose>
      </light>
      <light name='user_point_light_0_clone_1'>
        <pose>8.72559 -1.12474 3.52695 0 -0 0</pose>
      </light>
      <light name='user_point_light_0_clone_1_clone_clone'>
        <pose>19.9276 9.14268 3.52695 0 -0 0</pose>
      </light>
      <light name='user_point_light_1'>
        <pose>8.127 7.14402 0.338984 0 0 -0.687374</pose>
      </light>
    </state>
    <model name='Sharp_turn_left_long_2_legs'>
      <pose>15.705 -0.334015 0 0 -0 0</pose>
      <static>1</static>
      <link name='body'>
        <visual name='visual'>
          <geometry>
            <mesh>
              <uri>model://meshes/Sharp_turn_left_long_2_legs.dae</uri>
              <scale>1 1 1</scale>
            </mesh>
          </geometry>
        </visual>
        <self_collide>0</self_collide>
        <enable_wind>0</enable_wind>
        <kinematic>0</kinematic>
      </link>
    </model>
    <model name='Sharp_turn_left_long_2_legs_clone'>
      <pose>16.338 -0.378908 0 0 0 -1.53922</pose>
      <static>1</static>
      <link name='body'>
        <visual name='visual'>
          <geometry>
            <mesh>
              <uri>model://meshes/Sharp_turn_left_long_2_legs.dae</uri>
              <scale>1 1 1</scale>
            </mesh>
          </geometry>
        </visual>
        <self_collide>0</self_collide>
        <enable_wind>0</enable_wind>
        <kinematic>0</kinematic>
      </link>
    </model>
    <model name='Sharp_turn_left_short'>
      <pose>17.3679 -0.2901 0 0 -0 0</pose>
      <static>1</static>
      <link name='body'>
        <visual name='visual'>
          <geometry>
            <mesh>
              <uri>model://meshes/Sharp_turn_left_short.dae</uri>
              <scale>1 1 1</scale>
            </mesh>
          </geometry>
        </visual>
        <self_collide>0</self_collide>
        <enable_wind>0</enable_wind>
        <kinematic>0</kinematic>
      </link>
    </model>
    <model name='Sharp_turn_left_short_clone'>
      <pose>17.8024 -0.10579 0 0 0 -1.59471</pose>
      <static>1</static>
      <link name='body'>
        <visual name='visual'>
          <geometry>
            <mesh>
              <uri>model://meshes/Sharp_turn_left_short.dae</uri>
              <scale>1 1 1</scale>
            </mesh>
          </geometry>
        </visual>
        <self_collide>0</self_collide>
        <enable_wind>0</enable_wind>
        <kinematic>0</kinematic>
      </link>
    </model>
    <model name='Sharp_turn_left_short_clone_0'>
      <pose>18.1246 0.059282 0 0 0 -1.59471</pose>
      <static>1</static>
      <link name='body'>
        <visual name='visual'>
          <geometry>
            <mesh>
              <uri>model://meshes/Sharp_turn_left_short.dae</uri>
              <scale>1 1 1</scale>
            </mesh>
          </geometry>
        </visual>
        <self_collide>0</self_collide>
        <enable_wind>0</enable_wind>
        <kinematic>0</kinematic>
      </link>
    </model>
    <model name='Sharp_turn_left_short_clone_1'>
      <pose>18.4275 0.297757 0 0 0 -1.59471</pose>
      <static>1</static>
      <link name='body'>
        <visual name='visual'>
          <geometry>
            <mesh>
              <uri>model://meshes/Sharp_turn_left_short.dae</uri>
              <scale>1 1 1</scale>
            </mesh>
          </geometry>
        </visual>
        <self_collide>0</self_collide>
        <enable_wind>0</enable_wind>
        <kinematic>0</kinematic>
      </link>
    </model>
    <model name='Sharp_turn_left_short_clone_2'>
      <pose>18.5106 0.401209 0 0 0 -1.59471</pose>
      <static>1</static>
      <link name='body'>
        <visual name='visual'>
          <geometry>
            <mesh>
              <uri>model://meshes/Sharp_turn_left_short.dae</uri>
              <scale>1 1 1</scale>
            </mesh>
          </geometry>
        </visual>
        <self_collide>0</self_collide>
        <enable_wind>0</enable_wind>
        <kinematic>0</kinematic>
      </link>
    </model>
    <model name='Sharp_turn_left_short_clone_3'>
      <pose>18.7112 0.644653 0 0 0 -1.59471</pose>
      <static>1</static>
      <link name='body'>
        <visual name='visual'>
          <geometry>
            <mesh>
              <uri>model://meshes/Sharp_turn_left_short.dae</uri>
              <scale>1 1 1</scale>
            </mesh>
          </geometry>
        </visual>
        <self_collide>0</self_collide>
        <enable_wind>0</enable_wind>
        <kinematic>0</kinematic>
      </link>
    </model>
    <model name='Sharp_turn_left_short_clone_4'>
      <pose>18.8634 0.898232 0 0 0 -1.59471</pose>
      <static>1</static>
      <link name='body'>
        <visual name='visual'>
          <geometry>
            <mesh>
              <uri>model://meshes/Sharp_turn_left_short.dae</uri>
              <scale>1 1 1</scale>
            </mesh>
          </geometry>
        </visual>
        <self_collide>0</self_collide>
        <enable_wind>0</enable_wind>
        <kinematic>0</kinematic>
      </link>
    </model>
    <model name='Expressway_end'>
      <pose>16.6622 -0.320108 0 0 -0 0</pose>
      <static>1</static>
      <link name='body'>
        <visual name='visual'>
          <geometry>
            <mesh>
              <uri>model://meshes/Expressway_end.dae</uri>
              <scale>1 1 1</scale>
            </mesh>
          </geometry>
        </visual>
        <self_collide>0</self_collide>
        <enable_wind>0</enable_wind>
        <kinematic>0</kinematic>
      </link>
    </model>
    <model name='Zebra_crossing'>
      <pose>6.23893 8.02898 0 0 -0 0</pose>
      <static>1</static>
      <link name='body'>
        <visual name='visual'>
          <geometry>
            <mesh>
              <uri>model://meshes/Zebra_crossing.dae</uri>
              <scale>1 1 1</scale>
            </mesh>
          </geometry>
        </visual>
        <self_collide>0</self_collide>
        <enable_wind>0</enable_wind>
        <kinematic>0</kinematic>
      </link>
    </model>
    <model name='Pedestrian_island'>
      <pose>10.9016 3.54901 0 0 -0 0</pose>
      <static>1</static>
      <link name='body'>
        <visual name='visual'>
          <geometry>
            <mesh>
              <uri>model://meshes/Pedestrian_island.dae</uri>
              <scale>1 1 1</scale>
            </mesh>
          </geometry>
        </visual>
        <self_collide>0</self_collide>
        <enable_wind>0</enable_wind>
        <kinematic>0</kinematic>
      </link>
    </model>
    <model name='Downhill_grade'>
      <pose>19.0742 4.1645 0 0 -0 0</pose>
      <static>1</static>
      <link name='body'>
        <visual name='visual'>
          <geometry>
            <mesh>
              <uri>model://meshes/Downhill_grade.dae</uri>
              <scale>1 1 1</scale>
            </mesh>
          </geometry>
        </visual>
        <self_collide>0</self_collide>
        <enable_wind>0</enable_wind>
        <kinematic>0</kinematic>
      </link>
    </model>
    <model name='Uphill_grade'>
      <pose>19.0243 1.41754 0 0 -0 0</pose>
      <static>1</static>
      <link name='body'>
        <visual name='visual'>
          <geometry>
            <mesh>
              <uri>model://meshes/Uphill_grade.dae</uri>
              <scale>1 1 1</scale>
            </mesh>
          </geometry>
        </visual>
        <self_collide>0</self_collide>
        <enable_wind>0</enable_wind>
        <kinematic>0</kinematic>
      </link>
    </model>
    <model name='No_passing_zone_beginning'>
      <pose>19.0607 6.69914 0 0 -0 0</pose>
      <static>1</static>
      <link name='body'>
        <visual name='visual'>
          <geometry>
            <mesh>
              <uri>model://meshes/No_passing_zone_beginning.dae</uri>
              <scale>1 1 1</scale>
            </mesh>
          </geometry>
        </visual>
        <self_collide>0</self_collide>
        <enable_wind>0</enable_wind>
        <kinematic>0</kinematic>
      </link>
    </model>
    <model name='30_Zone'>
      <pose>14.8988 8.26058 0 0 -0 0</pose>
      <static>1</static>
      <link name='body'>
        <visual name='visual'>
          <geometry>
            <mesh>
              <uri>model://meshes/30_Zone.dae</uri>
              <scale>1 1 1</scale>
            </mesh>
          </geometry>
        </visual>
        <self_collide>0</self_collide>
        <enable_wind>0</enable_wind>
        <kinematic>0</kinematic>
      </link>
    </model>
    <model name='Left_turn'>
      <pose>14.2202 7.51193 0 0 -0 0</pose>
      <static>1</static>
      <link name='body'>
        <visual name='visual'>
          <geometry>
            <mesh>
              <uri>model://meshes/Left_turn.dae</uri>
              <scale>1 1 1</scale>
            </mesh>
          </geometry>
        </visual>
        <self_collide>0</self_collide>
        <enable_wind>0</enable_wind>
        <kinematic>0</kinematic>
      </link>
    </model>
    <model name='Preference'>
      <pose>14.3479 7.61733 0 0 -0 0</pose>
      <static>1</static>
      <link name='body'>
        <visual name='visual'>
          <geometry>
            <mesh>
              <uri>model://meshes/Preference.dae</uri>
              <scale>1 1 1</scale>
            </mesh>
          </geometry>
        </visual>
        <self_collide>0</self_collide>
        <enable_wind>0</enable_wind>
        <kinematic>0</kinematic>
      </link>
    </model>
    <model name='30_Zone_End'>
      <pose>8.5452 3.03846 0 0 -0 0</pose>
      <static>1</static>
      <link name='body'>
        <visual name='visual'>
          <geometry>
            <mesh>
              <uri>model://meshes/30_Zone_End.dae</uri>
              <scale>1 1 1</scale>
            </mesh>
          </geometry>
        </visual>
        <self_collide>0</self_collide>
        <enable_wind>0</enable_wind>
        <kinematic>0</kinematic>
      </link>
    </model>
    <light name='user_point_light_0_clone_1' type='point'>
      <pose>19.8845 4.93206 3.52695 0 -0 0</pose>
      <diffuse>0.494118 0.494118 0.494118 1</diffuse>
      <specular>0.0901961 0.0901961 0.0901961 1</specular>
      <direction>0 0 -1</direction>
      <attenuation>
        <range>30</range>
        <constant>0.1</constant>
        <linear>0</linear>
        <quadratic>0</quadratic>
      </attenuation>
      <cast_shadows>0</cast_shadows>
      <spot>
        <inner_angle>0</inner_angle>
        <outer_angle>0</outer_angle>
        <falloff>0</falloff>
      </spot>
    </light>
    <light name='user_point_light_0_clone_1_clone_clone' type='point'>
      <pose>19.9276 7.47045 3.52695 0 -0 0</pose>
      <diffuse>0.494118 0.494118 0.494118 1</diffuse>
      <specular>0.0901961 0.0901961 0.0901961 1</specular>
      <direction>0 0 -1</direction>
      <attenuation>
        <range>30</range>
        <constant>0.1</constant>
        <linear>0</linear>
        <quadratic>0</quadratic>
      </attenuation>
      <cast_shadows>0</cast_shadows>
      <spot>
        <inner_angle>0</inner_angle>
        <outer_angle>0</outer_angle>
        <falloff>0</falloff>
      </spot>
    </light>
    <model name='Stop'>
      <pose>7.40622 3.93788 0 0 -0 0</pose>
      <static>1</static>
      <link name='body'>
        <visual name='visual'>
          <geometry>
            <mesh>
              <uri>model://meshes/Stop.dae</uri>
              <scale>1 1 1</scale>
            </mesh>
          </geometry>
        </visual>
        <self_collide>0</self_collide>
        <enable_wind>0</enable_wind>
        <kinematic>0</kinematic>
      </link>
    </model>
    <model name='Preference_0'>
      <pose>6.63736 4.93916 0 0 -0 0</pose>
      <static>1</static>
      <link name='body'>
        <visual name='visual'>
          <geometry>
            <mesh>
              <uri>model://meshes/Preference.dae</uri>
              <scale>1 1 1</scale>
            </mesh>
          </geometry>
        </visual>
        <self_collide>0</self_collide>
        <enable_wind>0</enable_wind>
        <kinematic>0</kinematic>
      </link>
    </model>
    <model name='20_Zone'>
      <pose>5.64389 6.11196 0 0 -0 0</pose>
      <static>1</static>
      <link name='body'>
        <visual name='visual'>
          <geometry>
            <mesh>
              <uri>model://meshes/20_Zone.dae</uri>
              <scale>1 1 1</scale>
            </mesh>
          </geometry>
        </visual>
        <self_collide>0</self_collide>
        <enable_wind>0</enable_wind>
        <kinematic>0</kinematic>
      </link>
    </model>
    <model name='Stop_0'>
      <pose>5.18931 6.52736 0 0 -0 0</pose>
      <static>1</static>
      <link name='body'>
        <visual name='visual'>
          <geometry>
            <mesh>
              <uri>model://meshes/Stop.dae</uri>
              <scale>1 1 1</scale>
            </mesh>
          </geometry>
        </visual>
        <self_collide>0</self_collide>
        <enable_wind>0</enable_wind>
        <kinematic>0</kinematic>
      </link>
    </model>
    <model name='Right_turn'>
      <pose>5.06488 6.64673 0 0 -0 0</pose>
      <static>1</static>
      <link name='body'>
        <visual name='visual'>
          <geometry>
            <mesh>
              <uri>model://meshes/Right_turn.dae</uri>
              <scale>1 1 1</scale>
            </mesh>
          </geometry>
        </visual>
        <self_collide>0</self_collide>
        <enable_wind>0</enable_wind>
        <kinematic>0</kinematic>
      </link>
    </model>
    <model name='Barred_area'>
      <pose>5.0807 7.03321 0 0 -0 0</pose>
      <static>1</static>
      <link name='body'>
        <visual name='visual'>
          <geometry>
            <mesh>
              <uri>model://meshes/Barred_area.dae</uri>
              <scale>1 1 1</scale>
            </mesh>
          </geometry>
        </visual>
        <self_collide>0</self_collide>
        <enable_wind>0</enable_wind>
        <kinematic>0</kinematic>
      </link>
    </model>
    <model name='No_passing_zone_end'>
      <pose>14.9463 5.32498 0 0 -0 0</pose>
      <static>1</static>
      <link name='body'>
        <visual name='visual'>
          <geometry>
            <mesh>
              <uri>model://meshes/No_passing_zone_end.dae</uri>
              <scale>1 1 1</scale>
            </mesh>
          </geometry>
        </visual>
        <self_collide>0</self_collide>
        <enable_wind>0</enable_wind>
        <kinematic>0</kinematic>
      </link>
    </model>
    <model name='Give_way'>
      <pose>8.2402 7.01412 0 0 -0 0</pose>
      <static>1</static>
      <link name='body'>
        <visual name='visual'>
          <geometry>
            <mesh>
              <uri>model://meshes/Give_way.dae</uri>
              <scale>1 1 1</scale>
            </mesh>
          </geometry>
        </visual>
        <self_collide>0</self_collide>
        <enable_wind>0</enable_wind>
        <kinematic>0</kinematic>
      </link>
    </model>
    <model name='Right_turn_0'>
      <pose>8.42056 6.85361 0 0 -0 0</pose>
      <static>1</static>
      <link name='body'>
        <visual name='visual'>
          <geometry>
            <mesh>
              <uri>model://meshes/Right_turn.dae</uri>
              <scale>1 1 1</scale>
            </mesh>
          </geometry>
        </visual>
        <self_collide>0</self_collide>
        <enable_wind>0</enable_wind>
        <kinematic>0</kinematic>
      </link>
    </model>
    <light name='user_point_light_1' type='point'>
      <pose>8.05266 7.20504 1 0 -0 0</pose>
      <diffuse>0.5 0.5 0.5 1</diffuse>
      <specular>0.1 0.1 0.1 1</specular>
      <attenuation>
        <range>20</range>
        <constant>0.5</constant>
        <linear>0.01</linear>
        <quadratic>0.001</quadratic>
      </attenuation>
      <cast_shadows>0</cast_shadows>
      <direction>0 0 -1</direction>
      <spot>
        <inner_angle>0</inner_angle>
        <outer_angle>0</outer_angle>
        <falloff>0</falloff>
      </spot>
    </light>
    <model name='20_Zone_End'>
      <pose>7.97543 6.30189 0 0 -0 0</pose>
      <static>1</static>
      <link name='body'>
        <visual name='visual'>
          <geometry>
            <mesh>
              <uri>model://meshes/20_Zone_End.dae</uri>
              <scale>1 1 1</scale>
            </mesh>
          </geometry>
        </visual>
        <self_collide>0</self_collide>
        <enable_wind>0</enable_wind>
        <kinematic>0</kinematic>
      </link>
    </model>
    <gui fullscreen='0'>
      <camera name='user_camera'>
        <pose>20.8018 4.77612 1.61282 0 0.573799 2.03534</pose>
        <view_controller>orbit</view_controller>
        <projection_type>perspective</projection_type>
      </camera>
    </gui>
    <model name='Ramp'>
      <pose>18.5966 4.04487 0 0 -0 0</pose>
      <static>1</static>
      <link name='body'>
        <visual name='visual'>
          <geometry>
            <mesh>
              <uri>model://meshes/Ramp.dae</uri>
              <scale>1 1 1</scale>
            </mesh>
          </geometry>
        </visual>
        <self_collide>0</self_collide>
        <enable_wind>0</enable_wind>
        <kinematic>0</kinematic>
      </link>
    </model>
  </world>
</sdf>
